
2020-10-12 10:58:29,429 INFO: errors [in /home/alij/dev_personal/nano_degree/Udacity-Projects/projects/01_fyyur/starter_code/app.py:960]
2020-10-12 10:58:32,496 INFO: errors [in app.py:960]
2020-10-12 10:58:39,750 ERROR: Exception on /venues [GET] [in /home/alij/dev_personal/nano_degree/Udacity-Projects/projects/01_fyyur/starter_code/env/lib/python3.7/site-packages/flask/app.py:1892]
Traceback (most recent call last):
  File "/home/alij/dev_personal/nano_degree/Udacity-Projects/projects/01_fyyur/starter_code/env/lib/python3.7/site-packages/flask/app.py", line 2447, in wsgi_app
    response = self.full_dispatch_request()
  File "/home/alij/dev_personal/nano_degree/Udacity-Projects/projects/01_fyyur/starter_code/env/lib/python3.7/site-packages/flask/app.py", line 1952, in full_dispatch_request
    rv = self.handle_user_exception(e)
  File "/home/alij/dev_personal/nano_degree/Udacity-Projects/projects/01_fyyur/starter_code/env/lib/python3.7/site-packages/flask/app.py", line 1821, in handle_user_exception
    reraise(exc_type, exc_value, tb)
  File "/home/alij/dev_personal/nano_degree/Udacity-Projects/projects/01_fyyur/starter_code/env/lib/python3.7/site-packages/flask/_compat.py", line 39, in reraise
    raise value
  File "/home/alij/dev_personal/nano_degree/Udacity-Projects/projects/01_fyyur/starter_code/env/lib/python3.7/site-packages/flask/app.py", line 1950, in full_dispatch_request
    rv = self.dispatch_request()
  File "/home/alij/dev_personal/nano_degree/Udacity-Projects/projects/01_fyyur/starter_code/env/lib/python3.7/site-packages/flask/app.py", line 1936, in dispatch_request
    return self.view_functions[rule.endpoint](**req.view_args)
  File "app.py", line 73, in venues
    venues = Venue.query.all()
NameError: name 'Venue' is not defined
2020-10-12 11:03:37,597 INFO: errors [in app.py:960]
2020-10-12 11:03:44,075 ERROR: Exception on /venues [GET] [in /home/alij/dev_personal/nano_degree/Udacity-Projects/projects/01_fyyur/starter_code/env/lib/python3.7/site-packages/flask/app.py:1892]
Traceback (most recent call last):
  File "/home/alij/dev_personal/nano_degree/Udacity-Projects/projects/01_fyyur/starter_code/env/lib/python3.7/site-packages/sqlalchemy/util/_collections.py", line 1020, in __call__
    return self.registry[key]
KeyError: 140168108406528

During handling of the above exception, another exception occurred:

Traceback (most recent call last):
  File "/home/alij/dev_personal/nano_degree/Udacity-Projects/projects/01_fyyur/starter_code/env/lib/python3.7/site-packages/flask/app.py", line 2447, in wsgi_app
    response = self.full_dispatch_request()
  File "/home/alij/dev_personal/nano_degree/Udacity-Projects/projects/01_fyyur/starter_code/env/lib/python3.7/site-packages/flask/app.py", line 1952, in full_dispatch_request
    rv = self.handle_user_exception(e)
  File "/home/alij/dev_personal/nano_degree/Udacity-Projects/projects/01_fyyur/starter_code/env/lib/python3.7/site-packages/flask/app.py", line 1821, in handle_user_exception
    reraise(exc_type, exc_value, tb)
  File "/home/alij/dev_personal/nano_degree/Udacity-Projects/projects/01_fyyur/starter_code/env/lib/python3.7/site-packages/flask/_compat.py", line 39, in reraise
    raise value
  File "/home/alij/dev_personal/nano_degree/Udacity-Projects/projects/01_fyyur/starter_code/env/lib/python3.7/site-packages/flask/app.py", line 1950, in full_dispatch_request
    rv = self.dispatch_request()
  File "/home/alij/dev_personal/nano_degree/Udacity-Projects/projects/01_fyyur/starter_code/env/lib/python3.7/site-packages/flask/app.py", line 1936, in dispatch_request
    return self.view_functions[rule.endpoint](**req.view_args)
  File "app.py", line 73, in venues
    venues = Venue.query.all()
  File "/home/alij/dev_personal/nano_degree/Udacity-Projects/projects/01_fyyur/starter_code/env/lib/python3.7/site-packages/flask_sqlalchemy/__init__.py", line 514, in __get__
    return type.query_class(mapper, session=self.sa.session())
  File "/home/alij/dev_personal/nano_degree/Udacity-Projects/projects/01_fyyur/starter_code/env/lib/python3.7/site-packages/sqlalchemy/orm/scoping.py", line 78, in __call__
    return self.registry()
  File "/home/alij/dev_personal/nano_degree/Udacity-Projects/projects/01_fyyur/starter_code/env/lib/python3.7/site-packages/sqlalchemy/util/_collections.py", line 1022, in __call__
    return self.registry.setdefault(key, self.createfunc())
  File "/home/alij/dev_personal/nano_degree/Udacity-Projects/projects/01_fyyur/starter_code/env/lib/python3.7/site-packages/sqlalchemy/orm/session.py", line 3286, in __call__
    return self.class_(**local_kw)
  File "/home/alij/dev_personal/nano_degree/Udacity-Projects/projects/01_fyyur/starter_code/env/lib/python3.7/site-packages/flask_sqlalchemy/__init__.py", line 137, in __init__
    track_modifications = app.config['SQLALCHEMY_TRACK_MODIFICATIONS']
KeyError: 'SQLALCHEMY_TRACK_MODIFICATIONS'
2020-10-12 11:04:06,977 ERROR: Exception on /artists [GET] [in /home/alij/dev_personal/nano_degree/Udacity-Projects/projects/01_fyyur/starter_code/env/lib/python3.7/site-packages/flask/app.py:1892]
Traceback (most recent call last):
  File "/home/alij/dev_personal/nano_degree/Udacity-Projects/projects/01_fyyur/starter_code/env/lib/python3.7/site-packages/sqlalchemy/util/_collections.py", line 1020, in __call__
    return self.registry[key]
KeyError: 140168100013824

During handling of the above exception, another exception occurred:

Traceback (most recent call last):
  File "/home/alij/dev_personal/nano_degree/Udacity-Projects/projects/01_fyyur/starter_code/env/lib/python3.7/site-packages/flask/app.py", line 2447, in wsgi_app
    response = self.full_dispatch_request()
  File "/home/alij/dev_personal/nano_degree/Udacity-Projects/projects/01_fyyur/starter_code/env/lib/python3.7/site-packages/flask/app.py", line 1952, in full_dispatch_request
    rv = self.handle_user_exception(e)
  File "/home/alij/dev_personal/nano_degree/Udacity-Projects/projects/01_fyyur/starter_code/env/lib/python3.7/site-packages/flask/app.py", line 1821, in handle_user_exception
    reraise(exc_type, exc_value, tb)
  File "/home/alij/dev_personal/nano_degree/Udacity-Projects/projects/01_fyyur/starter_code/env/lib/python3.7/site-packages/flask/_compat.py", line 39, in reraise
    raise value
  File "/home/alij/dev_personal/nano_degree/Udacity-Projects/projects/01_fyyur/starter_code/env/lib/python3.7/site-packages/flask/app.py", line 1950, in full_dispatch_request
    rv = self.dispatch_request()
  File "/home/alij/dev_personal/nano_degree/Udacity-Projects/projects/01_fyyur/starter_code/env/lib/python3.7/site-packages/flask/app.py", line 1936, in dispatch_request
    return self.view_functions[rule.endpoint](**req.view_args)
  File "app.py", line 405, in artists
    all_artists = Artist.query.all()
  File "/home/alij/dev_personal/nano_degree/Udacity-Projects/projects/01_fyyur/starter_code/env/lib/python3.7/site-packages/flask_sqlalchemy/__init__.py", line 514, in __get__
    return type.query_class(mapper, session=self.sa.session())
  File "/home/alij/dev_personal/nano_degree/Udacity-Projects/projects/01_fyyur/starter_code/env/lib/python3.7/site-packages/sqlalchemy/orm/scoping.py", line 78, in __call__
    return self.registry()
  File "/home/alij/dev_personal/nano_degree/Udacity-Projects/projects/01_fyyur/starter_code/env/lib/python3.7/site-packages/sqlalchemy/util/_collections.py", line 1022, in __call__
    return self.registry.setdefault(key, self.createfunc())
  File "/home/alij/dev_personal/nano_degree/Udacity-Projects/projects/01_fyyur/starter_code/env/lib/python3.7/site-packages/sqlalchemy/orm/session.py", line 3286, in __call__
    return self.class_(**local_kw)
  File "/home/alij/dev_personal/nano_degree/Udacity-Projects/projects/01_fyyur/starter_code/env/lib/python3.7/site-packages/flask_sqlalchemy/__init__.py", line 137, in __init__
    track_modifications = app.config['SQLALCHEMY_TRACK_MODIFICATIONS']
KeyError: 'SQLALCHEMY_TRACK_MODIFICATIONS'
2020-10-12 11:04:09,248 ERROR: Exception on /shows [GET] [in /home/alij/dev_personal/nano_degree/Udacity-Projects/projects/01_fyyur/starter_code/env/lib/python3.7/site-packages/flask/app.py:1892]
Traceback (most recent call last):
  File "/home/alij/dev_personal/nano_degree/Udacity-Projects/projects/01_fyyur/starter_code/env/lib/python3.7/site-packages/sqlalchemy/util/_collections.py", line 1020, in __call__
    return self.registry[key]
KeyError: 140168100013824

During handling of the above exception, another exception occurred:

Traceback (most recent call last):
  File "/home/alij/dev_personal/nano_degree/Udacity-Projects/projects/01_fyyur/starter_code/env/lib/python3.7/site-packages/flask/app.py", line 2447, in wsgi_app
    response = self.full_dispatch_request()
  File "/home/alij/dev_personal/nano_degree/Udacity-Projects/projects/01_fyyur/starter_code/env/lib/python3.7/site-packages/flask/app.py", line 1952, in full_dispatch_request
    rv = self.handle_user_exception(e)
  File "/home/alij/dev_personal/nano_degree/Udacity-Projects/projects/01_fyyur/starter_code/env/lib/python3.7/site-packages/flask/app.py", line 1821, in handle_user_exception
    reraise(exc_type, exc_value, tb)
  File "/home/alij/dev_personal/nano_degree/Udacity-Projects/projects/01_fyyur/starter_code/env/lib/python3.7/site-packages/flask/_compat.py", line 39, in reraise
    raise value
  File "/home/alij/dev_personal/nano_degree/Udacity-Projects/projects/01_fyyur/starter_code/env/lib/python3.7/site-packages/flask/app.py", line 1950, in full_dispatch_request
    rv = self.dispatch_request()
  File "/home/alij/dev_personal/nano_degree/Udacity-Projects/projects/01_fyyur/starter_code/env/lib/python3.7/site-packages/flask/app.py", line 1936, in dispatch_request
    return self.view_functions[rule.endpoint](**req.view_args)
  File "app.py", line 843, in shows
    shows = Show.query.all()
  File "/home/alij/dev_personal/nano_degree/Udacity-Projects/projects/01_fyyur/starter_code/env/lib/python3.7/site-packages/flask_sqlalchemy/__init__.py", line 514, in __get__
    return type.query_class(mapper, session=self.sa.session())
  File "/home/alij/dev_personal/nano_degree/Udacity-Projects/projects/01_fyyur/starter_code/env/lib/python3.7/site-packages/sqlalchemy/orm/scoping.py", line 78, in __call__
    return self.registry()
  File "/home/alij/dev_personal/nano_degree/Udacity-Projects/projects/01_fyyur/starter_code/env/lib/python3.7/site-packages/sqlalchemy/util/_collections.py", line 1022, in __call__
    return self.registry.setdefault(key, self.createfunc())
  File "/home/alij/dev_personal/nano_degree/Udacity-Projects/projects/01_fyyur/starter_code/env/lib/python3.7/site-packages/sqlalchemy/orm/session.py", line 3286, in __call__
    return self.class_(**local_kw)
  File "/home/alij/dev_personal/nano_degree/Udacity-Projects/projects/01_fyyur/starter_code/env/lib/python3.7/site-packages/flask_sqlalchemy/__init__.py", line 137, in __init__
    track_modifications = app.config['SQLALCHEMY_TRACK_MODIFICATIONS']
KeyError: 'SQLALCHEMY_TRACK_MODIFICATIONS'
2020-10-12 11:04:11,823 ERROR: Exception on /venues/create [GET] [in /home/alij/dev_personal/nano_degree/Udacity-Projects/projects/01_fyyur/starter_code/env/lib/python3.7/site-packages/flask/app.py:1892]
Traceback (most recent call last):
  File "/home/alij/dev_personal/nano_degree/Udacity-Projects/projects/01_fyyur/starter_code/env/lib/python3.7/site-packages/flask/app.py", line 2447, in wsgi_app
    response = self.full_dispatch_request()
  File "/home/alij/dev_personal/nano_degree/Udacity-Projects/projects/01_fyyur/starter_code/env/lib/python3.7/site-packages/flask/app.py", line 1952, in full_dispatch_request
    rv = self.handle_user_exception(e)
  File "/home/alij/dev_personal/nano_degree/Udacity-Projects/projects/01_fyyur/starter_code/env/lib/python3.7/site-packages/flask/app.py", line 1821, in handle_user_exception
    reraise(exc_type, exc_value, tb)
  File "/home/alij/dev_personal/nano_degree/Udacity-Projects/projects/01_fyyur/starter_code/env/lib/python3.7/site-packages/flask/_compat.py", line 39, in reraise
    raise value
  File "/home/alij/dev_personal/nano_degree/Udacity-Projects/projects/01_fyyur/starter_code/env/lib/python3.7/site-packages/flask/app.py", line 1950, in full_dispatch_request
    rv = self.dispatch_request()
  File "/home/alij/dev_personal/nano_degree/Udacity-Projects/projects/01_fyyur/starter_code/env/lib/python3.7/site-packages/flask/app.py", line 1936, in dispatch_request
    return self.view_functions[rule.endpoint](**req.view_args)
  File "app.py", line 322, in create_venue_form
    form = VenueForm()
  File "/home/alij/dev_personal/nano_degree/Udacity-Projects/projects/01_fyyur/starter_code/env/lib/python3.7/site-packages/wtforms/form.py", line 208, in __call__
    return type.__call__(cls, *args, **kwargs)
  File "/home/alij/dev_personal/nano_degree/Udacity-Projects/projects/01_fyyur/starter_code/env/lib/python3.7/site-packages/flask_wtf/form.py", line 87, in __init__
    super(FlaskForm, self).__init__(formdata=formdata, **kwargs)
  File "/home/alij/dev_personal/nano_degree/Udacity-Projects/projects/01_fyyur/starter_code/env/lib/python3.7/site-packages/wtforms/form.py", line 274, in __init__
    self.process(formdata, obj, data=data, **kwargs)
  File "/home/alij/dev_personal/nano_degree/Udacity-Projects/projects/01_fyyur/starter_code/env/lib/python3.7/site-packages/wtforms/form.py", line 131, in process
    field.process(formdata)
  File "/home/alij/dev_personal/nano_degree/Udacity-Projects/projects/01_fyyur/starter_code/env/lib/python3.7/site-packages/wtforms/csrf/core.py", line 43, in process
    self.current_token = self.csrf_impl.generate_csrf_token(self)
  File "/home/alij/dev_personal/nano_degree/Udacity-Projects/projects/01_fyyur/starter_code/env/lib/python3.7/site-packages/flask_wtf/csrf.py", line 141, in generate_csrf_token
    token_key=self.meta.csrf_field_name
  File "/home/alij/dev_personal/nano_degree/Udacity-Projects/projects/01_fyyur/starter_code/env/lib/python3.7/site-packages/flask_wtf/csrf.py", line 35, in generate_csrf
    message='A secret key is required to use CSRF.'
  File "/home/alij/dev_personal/nano_degree/Udacity-Projects/projects/01_fyyur/starter_code/env/lib/python3.7/site-packages/flask_wtf/csrf.py", line 128, in _get_config
    raise RuntimeError(message)
RuntimeError: A secret key is required to use CSRF.
2020-10-12 11:04:13,707 ERROR: Exception on /venues [GET] [in /home/alij/dev_personal/nano_degree/Udacity-Projects/projects/01_fyyur/starter_code/env/lib/python3.7/site-packages/flask/app.py:1892]
Traceback (most recent call last):
  File "/home/alij/dev_personal/nano_degree/Udacity-Projects/projects/01_fyyur/starter_code/env/lib/python3.7/site-packages/sqlalchemy/util/_collections.py", line 1020, in __call__
    return self.registry[key]
KeyError: 140168100013824

During handling of the above exception, another exception occurred:

Traceback (most recent call last):
  File "/home/alij/dev_personal/nano_degree/Udacity-Projects/projects/01_fyyur/starter_code/env/lib/python3.7/site-packages/flask/app.py", line 2447, in wsgi_app
    response = self.full_dispatch_request()
  File "/home/alij/dev_personal/nano_degree/Udacity-Projects/projects/01_fyyur/starter_code/env/lib/python3.7/site-packages/flask/app.py", line 1952, in full_dispatch_request
    rv = self.handle_user_exception(e)
  File "/home/alij/dev_personal/nano_degree/Udacity-Projects/projects/01_fyyur/starter_code/env/lib/python3.7/site-packages/flask/app.py", line 1821, in handle_user_exception
    reraise(exc_type, exc_value, tb)
  File "/home/alij/dev_personal/nano_degree/Udacity-Projects/projects/01_fyyur/starter_code/env/lib/python3.7/site-packages/flask/_compat.py", line 39, in reraise
    raise value
  File "/home/alij/dev_personal/nano_degree/Udacity-Projects/projects/01_fyyur/starter_code/env/lib/python3.7/site-packages/flask/app.py", line 1950, in full_dispatch_request
    rv = self.dispatch_request()
  File "/home/alij/dev_personal/nano_degree/Udacity-Projects/projects/01_fyyur/starter_code/env/lib/python3.7/site-packages/flask/app.py", line 1936, in dispatch_request
    return self.view_functions[rule.endpoint](**req.view_args)
  File "app.py", line 73, in venues
    venues = Venue.query.all()
  File "/home/alij/dev_personal/nano_degree/Udacity-Projects/projects/01_fyyur/starter_code/env/lib/python3.7/site-packages/flask_sqlalchemy/__init__.py", line 514, in __get__
    return type.query_class(mapper, session=self.sa.session())
  File "/home/alij/dev_personal/nano_degree/Udacity-Projects/projects/01_fyyur/starter_code/env/lib/python3.7/site-packages/sqlalchemy/orm/scoping.py", line 78, in __call__
    return self.registry()
  File "/home/alij/dev_personal/nano_degree/Udacity-Projects/projects/01_fyyur/starter_code/env/lib/python3.7/site-packages/sqlalchemy/util/_collections.py", line 1022, in __call__
    return self.registry.setdefault(key, self.createfunc())
  File "/home/alij/dev_personal/nano_degree/Udacity-Projects/projects/01_fyyur/starter_code/env/lib/python3.7/site-packages/sqlalchemy/orm/session.py", line 3286, in __call__
    return self.class_(**local_kw)
  File "/home/alij/dev_personal/nano_degree/Udacity-Projects/projects/01_fyyur/starter_code/env/lib/python3.7/site-packages/flask_sqlalchemy/__init__.py", line 137, in __init__
    track_modifications = app.config['SQLALCHEMY_TRACK_MODIFICATIONS']
KeyError: 'SQLALCHEMY_TRACK_MODIFICATIONS'
2020-10-12 11:04:15,645 ERROR: Exception on /shows/create [GET] [in /home/alij/dev_personal/nano_degree/Udacity-Projects/projects/01_fyyur/starter_code/env/lib/python3.7/site-packages/flask/app.py:1892]
Traceback (most recent call last):
  File "/home/alij/dev_personal/nano_degree/Udacity-Projects/projects/01_fyyur/starter_code/env/lib/python3.7/site-packages/flask/app.py", line 2447, in wsgi_app
    response = self.full_dispatch_request()
  File "/home/alij/dev_personal/nano_degree/Udacity-Projects/projects/01_fyyur/starter_code/env/lib/python3.7/site-packages/flask/app.py", line 1952, in full_dispatch_request
    rv = self.handle_user_exception(e)
  File "/home/alij/dev_personal/nano_degree/Udacity-Projects/projects/01_fyyur/starter_code/env/lib/python3.7/site-packages/flask/app.py", line 1821, in handle_user_exception
    reraise(exc_type, exc_value, tb)
  File "/home/alij/dev_personal/nano_degree/Udacity-Projects/projects/01_fyyur/starter_code/env/lib/python3.7/site-packages/flask/_compat.py", line 39, in reraise
    raise value
  File "/home/alij/dev_personal/nano_degree/Udacity-Projects/projects/01_fyyur/starter_code/env/lib/python3.7/site-packages/flask/app.py", line 1950, in full_dispatch_request
    rv = self.dispatch_request()
  File "/home/alij/dev_personal/nano_degree/Udacity-Projects/projects/01_fyyur/starter_code/env/lib/python3.7/site-packages/flask/app.py", line 1936, in dispatch_request
    return self.view_functions[rule.endpoint](**req.view_args)
  File "app.py", line 905, in create_shows
    form = ShowForm()
  File "/home/alij/dev_personal/nano_degree/Udacity-Projects/projects/01_fyyur/starter_code/env/lib/python3.7/site-packages/wtforms/form.py", line 208, in __call__
    return type.__call__(cls, *args, **kwargs)
  File "/home/alij/dev_personal/nano_degree/Udacity-Projects/projects/01_fyyur/starter_code/env/lib/python3.7/site-packages/flask_wtf/form.py", line 87, in __init__
    super(FlaskForm, self).__init__(formdata=formdata, **kwargs)
  File "/home/alij/dev_personal/nano_degree/Udacity-Projects/projects/01_fyyur/starter_code/env/lib/python3.7/site-packages/wtforms/form.py", line 274, in __init__
    self.process(formdata, obj, data=data, **kwargs)
  File "/home/alij/dev_personal/nano_degree/Udacity-Projects/projects/01_fyyur/starter_code/env/lib/python3.7/site-packages/wtforms/form.py", line 131, in process
    field.process(formdata)
  File "/home/alij/dev_personal/nano_degree/Udacity-Projects/projects/01_fyyur/starter_code/env/lib/python3.7/site-packages/wtforms/csrf/core.py", line 43, in process
    self.current_token = self.csrf_impl.generate_csrf_token(self)
  File "/home/alij/dev_personal/nano_degree/Udacity-Projects/projects/01_fyyur/starter_code/env/lib/python3.7/site-packages/flask_wtf/csrf.py", line 141, in generate_csrf_token
    token_key=self.meta.csrf_field_name
  File "/home/alij/dev_personal/nano_degree/Udacity-Projects/projects/01_fyyur/starter_code/env/lib/python3.7/site-packages/flask_wtf/csrf.py", line 35, in generate_csrf
    message='A secret key is required to use CSRF.'
  File "/home/alij/dev_personal/nano_degree/Udacity-Projects/projects/01_fyyur/starter_code/env/lib/python3.7/site-packages/flask_wtf/csrf.py", line 128, in _get_config
    raise RuntimeError(message)
RuntimeError: A secret key is required to use CSRF.
2020-10-12 11:04:47,354 INFO: errors [in app.py:960]
2020-10-12 11:04:49,790 ERROR: Exception on /shows [GET] [in /home/alij/dev_personal/nano_degree/Udacity-Projects/projects/01_fyyur/starter_code/env/lib/python3.7/site-packages/flask/app.py:1892]
Traceback (most recent call last):
  File "/home/alij/dev_personal/nano_degree/Udacity-Projects/projects/01_fyyur/starter_code/env/lib/python3.7/site-packages/sqlalchemy/util/_collections.py", line 1020, in __call__
    return self.registry[key]
KeyError: 140251368146688

During handling of the above exception, another exception occurred:

Traceback (most recent call last):
  File "/home/alij/dev_personal/nano_degree/Udacity-Projects/projects/01_fyyur/starter_code/env/lib/python3.7/site-packages/flask/app.py", line 2447, in wsgi_app
    response = self.full_dispatch_request()
  File "/home/alij/dev_personal/nano_degree/Udacity-Projects/projects/01_fyyur/starter_code/env/lib/python3.7/site-packages/flask/app.py", line 1952, in full_dispatch_request
    rv = self.handle_user_exception(e)
  File "/home/alij/dev_personal/nano_degree/Udacity-Projects/projects/01_fyyur/starter_code/env/lib/python3.7/site-packages/flask/app.py", line 1821, in handle_user_exception
    reraise(exc_type, exc_value, tb)
  File "/home/alij/dev_personal/nano_degree/Udacity-Projects/projects/01_fyyur/starter_code/env/lib/python3.7/site-packages/flask/_compat.py", line 39, in reraise
    raise value
  File "/home/alij/dev_personal/nano_degree/Udacity-Projects/projects/01_fyyur/starter_code/env/lib/python3.7/site-packages/flask/app.py", line 1950, in full_dispatch_request
    rv = self.dispatch_request()
  File "/home/alij/dev_personal/nano_degree/Udacity-Projects/projects/01_fyyur/starter_code/env/lib/python3.7/site-packages/flask/app.py", line 1936, in dispatch_request
    return self.view_functions[rule.endpoint](**req.view_args)
  File "app.py", line 843, in shows
    shows = Show.query.all()
  File "/home/alij/dev_personal/nano_degree/Udacity-Projects/projects/01_fyyur/starter_code/env/lib/python3.7/site-packages/flask_sqlalchemy/__init__.py", line 514, in __get__
    return type.query_class(mapper, session=self.sa.session())
  File "/home/alij/dev_personal/nano_degree/Udacity-Projects/projects/01_fyyur/starter_code/env/lib/python3.7/site-packages/sqlalchemy/orm/scoping.py", line 78, in __call__
    return self.registry()
  File "/home/alij/dev_personal/nano_degree/Udacity-Projects/projects/01_fyyur/starter_code/env/lib/python3.7/site-packages/sqlalchemy/util/_collections.py", line 1022, in __call__
    return self.registry.setdefault(key, self.createfunc())
  File "/home/alij/dev_personal/nano_degree/Udacity-Projects/projects/01_fyyur/starter_code/env/lib/python3.7/site-packages/sqlalchemy/orm/session.py", line 3286, in __call__
    return self.class_(**local_kw)
  File "/home/alij/dev_personal/nano_degree/Udacity-Projects/projects/01_fyyur/starter_code/env/lib/python3.7/site-packages/flask_sqlalchemy/__init__.py", line 137, in __init__
    track_modifications = app.config['SQLALCHEMY_TRACK_MODIFICATIONS']
KeyError: 'SQLALCHEMY_TRACK_MODIFICATIONS'
2020-10-12 11:04:51,260 ERROR: Exception on /venues [GET] [in /home/alij/dev_personal/nano_degree/Udacity-Projects/projects/01_fyyur/starter_code/env/lib/python3.7/site-packages/flask/app.py:1892]
Traceback (most recent call last):
  File "/home/alij/dev_personal/nano_degree/Udacity-Projects/projects/01_fyyur/starter_code/env/lib/python3.7/site-packages/sqlalchemy/util/_collections.py", line 1020, in __call__
    return self.registry[key]
KeyError: 140251284633344

During handling of the above exception, another exception occurred:

Traceback (most recent call last):
  File "/home/alij/dev_personal/nano_degree/Udacity-Projects/projects/01_fyyur/starter_code/env/lib/python3.7/site-packages/flask/app.py", line 2447, in wsgi_app
    response = self.full_dispatch_request()
  File "/home/alij/dev_personal/nano_degree/Udacity-Projects/projects/01_fyyur/starter_code/env/lib/python3.7/site-packages/flask/app.py", line 1952, in full_dispatch_request
    rv = self.handle_user_exception(e)
  File "/home/alij/dev_personal/nano_degree/Udacity-Projects/projects/01_fyyur/starter_code/env/lib/python3.7/site-packages/flask/app.py", line 1821, in handle_user_exception
    reraise(exc_type, exc_value, tb)
  File "/home/alij/dev_personal/nano_degree/Udacity-Projects/projects/01_fyyur/starter_code/env/lib/python3.7/site-packages/flask/_compat.py", line 39, in reraise
    raise value
  File "/home/alij/dev_personal/nano_degree/Udacity-Projects/projects/01_fyyur/starter_code/env/lib/python3.7/site-packages/flask/app.py", line 1950, in full_dispatch_request
    rv = self.dispatch_request()
  File "/home/alij/dev_personal/nano_degree/Udacity-Projects/projects/01_fyyur/starter_code/env/lib/python3.7/site-packages/flask/app.py", line 1936, in dispatch_request
    return self.view_functions[rule.endpoint](**req.view_args)
  File "app.py", line 73, in venues
    venues = Venue.query.all()
  File "/home/alij/dev_personal/nano_degree/Udacity-Projects/projects/01_fyyur/starter_code/env/lib/python3.7/site-packages/flask_sqlalchemy/__init__.py", line 514, in __get__
    return type.query_class(mapper, session=self.sa.session())
  File "/home/alij/dev_personal/nano_degree/Udacity-Projects/projects/01_fyyur/starter_code/env/lib/python3.7/site-packages/sqlalchemy/orm/scoping.py", line 78, in __call__
    return self.registry()
  File "/home/alij/dev_personal/nano_degree/Udacity-Projects/projects/01_fyyur/starter_code/env/lib/python3.7/site-packages/sqlalchemy/util/_collections.py", line 1022, in __call__
    return self.registry.setdefault(key, self.createfunc())
  File "/home/alij/dev_personal/nano_degree/Udacity-Projects/projects/01_fyyur/starter_code/env/lib/python3.7/site-packages/sqlalchemy/orm/session.py", line 3286, in __call__
    return self.class_(**local_kw)
  File "/home/alij/dev_personal/nano_degree/Udacity-Projects/projects/01_fyyur/starter_code/env/lib/python3.7/site-packages/flask_sqlalchemy/__init__.py", line 137, in __init__
    track_modifications = app.config['SQLALCHEMY_TRACK_MODIFICATIONS']
KeyError: 'SQLALCHEMY_TRACK_MODIFICATIONS'
2020-10-12 11:04:53,365 ERROR: Exception on /venues [GET] [in /home/alij/dev_personal/nano_degree/Udacity-Projects/projects/01_fyyur/starter_code/env/lib/python3.7/site-packages/flask/app.py:1892]
Traceback (most recent call last):
  File "/home/alij/dev_personal/nano_degree/Udacity-Projects/projects/01_fyyur/starter_code/env/lib/python3.7/site-packages/sqlalchemy/util/_collections.py", line 1020, in __call__
    return self.registry[key]
KeyError: 140251284633344

During handling of the above exception, another exception occurred:

Traceback (most recent call last):
  File "/home/alij/dev_personal/nano_degree/Udacity-Projects/projects/01_fyyur/starter_code/env/lib/python3.7/site-packages/flask/app.py", line 2447, in wsgi_app
    response = self.full_dispatch_request()
  File "/home/alij/dev_personal/nano_degree/Udacity-Projects/projects/01_fyyur/starter_code/env/lib/python3.7/site-packages/flask/app.py", line 1952, in full_dispatch_request
    rv = self.handle_user_exception(e)
  File "/home/alij/dev_personal/nano_degree/Udacity-Projects/projects/01_fyyur/starter_code/env/lib/python3.7/site-packages/flask/app.py", line 1821, in handle_user_exception
    reraise(exc_type, exc_value, tb)
  File "/home/alij/dev_personal/nano_degree/Udacity-Projects/projects/01_fyyur/starter_code/env/lib/python3.7/site-packages/flask/_compat.py", line 39, in reraise
    raise value
  File "/home/alij/dev_personal/nano_degree/Udacity-Projects/projects/01_fyyur/starter_code/env/lib/python3.7/site-packages/flask/app.py", line 1950, in full_dispatch_request
    rv = self.dispatch_request()
  File "/home/alij/dev_personal/nano_degree/Udacity-Projects/projects/01_fyyur/starter_code/env/lib/python3.7/site-packages/flask/app.py", line 1936, in dispatch_request
    return self.view_functions[rule.endpoint](**req.view_args)
  File "app.py", line 73, in venues
    venues = Venue.query.all()
  File "/home/alij/dev_personal/nano_degree/Udacity-Projects/projects/01_fyyur/starter_code/env/lib/python3.7/site-packages/flask_sqlalchemy/__init__.py", line 514, in __get__
    return type.query_class(mapper, session=self.sa.session())
  File "/home/alij/dev_personal/nano_degree/Udacity-Projects/projects/01_fyyur/starter_code/env/lib/python3.7/site-packages/sqlalchemy/orm/scoping.py", line 78, in __call__
    return self.registry()
  File "/home/alij/dev_personal/nano_degree/Udacity-Projects/projects/01_fyyur/starter_code/env/lib/python3.7/site-packages/sqlalchemy/util/_collections.py", line 1022, in __call__
    return self.registry.setdefault(key, self.createfunc())
  File "/home/alij/dev_personal/nano_degree/Udacity-Projects/projects/01_fyyur/starter_code/env/lib/python3.7/site-packages/sqlalchemy/orm/session.py", line 3286, in __call__
    return self.class_(**local_kw)
  File "/home/alij/dev_personal/nano_degree/Udacity-Projects/projects/01_fyyur/starter_code/env/lib/python3.7/site-packages/flask_sqlalchemy/__init__.py", line 137, in __init__
    track_modifications = app.config['SQLALCHEMY_TRACK_MODIFICATIONS']
KeyError: 'SQLALCHEMY_TRACK_MODIFICATIONS'
2020-10-12 11:06:15,332 INFO: errors [in /home/alij/dev_personal/nano_degree/Udacity-Projects/projects/01_fyyur/starter_code/app.py:960]
2020-10-12 11:09:32,409 INFO: errors [in app.py:960]
2020-10-12 11:09:40,155 ERROR: Exception on /venues [GET] [in /home/alij/dev_personal/nano_degree/Udacity-Projects/projects/01_fyyur/starter_code/env/lib/python3.7/site-packages/flask/app.py:1892]
Traceback (most recent call last):
  File "/home/alij/dev_personal/nano_degree/Udacity-Projects/projects/01_fyyur/starter_code/env/lib/python3.7/site-packages/sqlalchemy/util/_collections.py", line 1020, in __call__
    return self.registry[key]
KeyError: 140159081219840

During handling of the above exception, another exception occurred:

Traceback (most recent call last):
  File "/home/alij/dev_personal/nano_degree/Udacity-Projects/projects/01_fyyur/starter_code/env/lib/python3.7/site-packages/flask/app.py", line 2447, in wsgi_app
    response = self.full_dispatch_request()
  File "/home/alij/dev_personal/nano_degree/Udacity-Projects/projects/01_fyyur/starter_code/env/lib/python3.7/site-packages/flask/app.py", line 1952, in full_dispatch_request
    rv = self.handle_user_exception(e)
  File "/home/alij/dev_personal/nano_degree/Udacity-Projects/projects/01_fyyur/starter_code/env/lib/python3.7/site-packages/flask/app.py", line 1821, in handle_user_exception
    reraise(exc_type, exc_value, tb)
  File "/home/alij/dev_personal/nano_degree/Udacity-Projects/projects/01_fyyur/starter_code/env/lib/python3.7/site-packages/flask/_compat.py", line 39, in reraise
    raise value
  File "/home/alij/dev_personal/nano_degree/Udacity-Projects/projects/01_fyyur/starter_code/env/lib/python3.7/site-packages/flask/app.py", line 1950, in full_dispatch_request
    rv = self.dispatch_request()
  File "/home/alij/dev_personal/nano_degree/Udacity-Projects/projects/01_fyyur/starter_code/env/lib/python3.7/site-packages/flask/app.py", line 1936, in dispatch_request
    return self.view_functions[rule.endpoint](**req.view_args)
  File "app.py", line 73, in venues
    venues = Venue.query.all()
  File "/home/alij/dev_personal/nano_degree/Udacity-Projects/projects/01_fyyur/starter_code/env/lib/python3.7/site-packages/flask_sqlalchemy/__init__.py", line 514, in __get__
    return type.query_class(mapper, session=self.sa.session())
  File "/home/alij/dev_personal/nano_degree/Udacity-Projects/projects/01_fyyur/starter_code/env/lib/python3.7/site-packages/sqlalchemy/orm/scoping.py", line 78, in __call__
    return self.registry()
  File "/home/alij/dev_personal/nano_degree/Udacity-Projects/projects/01_fyyur/starter_code/env/lib/python3.7/site-packages/sqlalchemy/util/_collections.py", line 1022, in __call__
    return self.registry.setdefault(key, self.createfunc())
  File "/home/alij/dev_personal/nano_degree/Udacity-Projects/projects/01_fyyur/starter_code/env/lib/python3.7/site-packages/sqlalchemy/orm/session.py", line 3286, in __call__
    return self.class_(**local_kw)
  File "/home/alij/dev_personal/nano_degree/Udacity-Projects/projects/01_fyyur/starter_code/env/lib/python3.7/site-packages/flask_sqlalchemy/__init__.py", line 137, in __init__
    track_modifications = app.config['SQLALCHEMY_TRACK_MODIFICATIONS']
KeyError: 'SQLALCHEMY_TRACK_MODIFICATIONS'
2020-10-12 11:11:19,770 INFO: errors [in app.py:960]
2020-10-12 11:11:46,054 INFO: errors [in /home/alij/dev_personal/nano_degree/Udacity-Projects/projects/01_fyyur/starter_code/app.py:960]
2020-10-12 11:11:57,693 INFO: errors [in /home/alij/dev_personal/nano_degree/Udacity-Projects/projects/01_fyyur/starter_code/app.py:960]
2020-10-12 11:12:05,097 INFO: errors [in app.py:960]
2020-10-12 11:12:14,619 ERROR: Exception on /shows [GET] [in /home/alij/dev_personal/nano_degree/Udacity-Projects/projects/01_fyyur/starter_code/env/lib/python3.7/site-packages/flask/app.py:1892]
Traceback (most recent call last):
  File "/home/alij/dev_personal/nano_degree/Udacity-Projects/projects/01_fyyur/starter_code/env/lib/python3.7/site-packages/sqlalchemy/util/_collections.py", line 1020, in __call__
    return self.registry[key]
KeyError: 139992714180352

During handling of the above exception, another exception occurred:

Traceback (most recent call last):
  File "/home/alij/dev_personal/nano_degree/Udacity-Projects/projects/01_fyyur/starter_code/env/lib/python3.7/site-packages/flask/app.py", line 2447, in wsgi_app
    response = self.full_dispatch_request()
  File "/home/alij/dev_personal/nano_degree/Udacity-Projects/projects/01_fyyur/starter_code/env/lib/python3.7/site-packages/flask/app.py", line 1952, in full_dispatch_request
    rv = self.handle_user_exception(e)
  File "/home/alij/dev_personal/nano_degree/Udacity-Projects/projects/01_fyyur/starter_code/env/lib/python3.7/site-packages/flask/app.py", line 1821, in handle_user_exception
    reraise(exc_type, exc_value, tb)
  File "/home/alij/dev_personal/nano_degree/Udacity-Projects/projects/01_fyyur/starter_code/env/lib/python3.7/site-packages/flask/_compat.py", line 39, in reraise
    raise value
  File "/home/alij/dev_personal/nano_degree/Udacity-Projects/projects/01_fyyur/starter_code/env/lib/python3.7/site-packages/flask/app.py", line 1950, in full_dispatch_request
    rv = self.dispatch_request()
  File "/home/alij/dev_personal/nano_degree/Udacity-Projects/projects/01_fyyur/starter_code/env/lib/python3.7/site-packages/flask/app.py", line 1936, in dispatch_request
    return self.view_functions[rule.endpoint](**req.view_args)
  File "app.py", line 843, in shows
    shows = Show.query.all()
  File "/home/alij/dev_personal/nano_degree/Udacity-Projects/projects/01_fyyur/starter_code/env/lib/python3.7/site-packages/flask_sqlalchemy/__init__.py", line 514, in __get__
    return type.query_class(mapper, session=self.sa.session())
  File "/home/alij/dev_personal/nano_degree/Udacity-Projects/projects/01_fyyur/starter_code/env/lib/python3.7/site-packages/sqlalchemy/orm/scoping.py", line 78, in __call__
    return self.registry()
  File "/home/alij/dev_personal/nano_degree/Udacity-Projects/projects/01_fyyur/starter_code/env/lib/python3.7/site-packages/sqlalchemy/util/_collections.py", line 1022, in __call__
    return self.registry.setdefault(key, self.createfunc())
  File "/home/alij/dev_personal/nano_degree/Udacity-Projects/projects/01_fyyur/starter_code/env/lib/python3.7/site-packages/sqlalchemy/orm/session.py", line 3286, in __call__
    return self.class_(**local_kw)
  File "/home/alij/dev_personal/nano_degree/Udacity-Projects/projects/01_fyyur/starter_code/env/lib/python3.7/site-packages/flask_sqlalchemy/__init__.py", line 137, in __init__
    track_modifications = app.config['SQLALCHEMY_TRACK_MODIFICATIONS']
KeyError: 'SQLALCHEMY_TRACK_MODIFICATIONS'
2020-10-12 11:12:15,269 ERROR: Exception on /artists [GET] [in /home/alij/dev_personal/nano_degree/Udacity-Projects/projects/01_fyyur/starter_code/env/lib/python3.7/site-packages/flask/app.py:1892]
Traceback (most recent call last):
  File "/home/alij/dev_personal/nano_degree/Udacity-Projects/projects/01_fyyur/starter_code/env/lib/python3.7/site-packages/sqlalchemy/util/_collections.py", line 1020, in __call__
    return self.registry[key]
KeyError: 139993060095744

During handling of the above exception, another exception occurred:

Traceback (most recent call last):
  File "/home/alij/dev_personal/nano_degree/Udacity-Projects/projects/01_fyyur/starter_code/env/lib/python3.7/site-packages/flask/app.py", line 2447, in wsgi_app
    response = self.full_dispatch_request()
  File "/home/alij/dev_personal/nano_degree/Udacity-Projects/projects/01_fyyur/starter_code/env/lib/python3.7/site-packages/flask/app.py", line 1952, in full_dispatch_request
    rv = self.handle_user_exception(e)
  File "/home/alij/dev_personal/nano_degree/Udacity-Projects/projects/01_fyyur/starter_code/env/lib/python3.7/site-packages/flask/app.py", line 1821, in handle_user_exception
    reraise(exc_type, exc_value, tb)
  File "/home/alij/dev_personal/nano_degree/Udacity-Projects/projects/01_fyyur/starter_code/env/lib/python3.7/site-packages/flask/_compat.py", line 39, in reraise
    raise value
  File "/home/alij/dev_personal/nano_degree/Udacity-Projects/projects/01_fyyur/starter_code/env/lib/python3.7/site-packages/flask/app.py", line 1950, in full_dispatch_request
    rv = self.dispatch_request()
  File "/home/alij/dev_personal/nano_degree/Udacity-Projects/projects/01_fyyur/starter_code/env/lib/python3.7/site-packages/flask/app.py", line 1936, in dispatch_request
    return self.view_functions[rule.endpoint](**req.view_args)
  File "app.py", line 405, in artists
    all_artists = Artist.query.all()
  File "/home/alij/dev_personal/nano_degree/Udacity-Projects/projects/01_fyyur/starter_code/env/lib/python3.7/site-packages/flask_sqlalchemy/__init__.py", line 514, in __get__
    return type.query_class(mapper, session=self.sa.session())
  File "/home/alij/dev_personal/nano_degree/Udacity-Projects/projects/01_fyyur/starter_code/env/lib/python3.7/site-packages/sqlalchemy/orm/scoping.py", line 78, in __call__
    return self.registry()
  File "/home/alij/dev_personal/nano_degree/Udacity-Projects/projects/01_fyyur/starter_code/env/lib/python3.7/site-packages/sqlalchemy/util/_collections.py", line 1022, in __call__
    return self.registry.setdefault(key, self.createfunc())
  File "/home/alij/dev_personal/nano_degree/Udacity-Projects/projects/01_fyyur/starter_code/env/lib/python3.7/site-packages/sqlalchemy/orm/session.py", line 3286, in __call__
    return self.class_(**local_kw)
  File "/home/alij/dev_personal/nano_degree/Udacity-Projects/projects/01_fyyur/starter_code/env/lib/python3.7/site-packages/flask_sqlalchemy/__init__.py", line 137, in __init__
    track_modifications = app.config['SQLALCHEMY_TRACK_MODIFICATIONS']
KeyError: 'SQLALCHEMY_TRACK_MODIFICATIONS'
2020-10-12 11:12:46,487 INFO: errors [in app.py:960]
2020-10-12 11:12:48,433 ERROR: Exception on /venues [GET] [in /home/alij/dev_personal/nano_degree/Udacity-Projects/projects/01_fyyur/starter_code/env/lib/python3.7/site-packages/flask/app.py:1892]
Traceback (most recent call last):
  File "/home/alij/dev_personal/nano_degree/Udacity-Projects/projects/01_fyyur/starter_code/env/lib/python3.7/site-packages/sqlalchemy/util/_collections.py", line 1020, in __call__
    return self.registry[key]
KeyError: 140668839970560

During handling of the above exception, another exception occurred:

Traceback (most recent call last):
  File "/home/alij/dev_personal/nano_degree/Udacity-Projects/projects/01_fyyur/starter_code/env/lib/python3.7/site-packages/flask/app.py", line 2447, in wsgi_app
    response = self.full_dispatch_request()
  File "/home/alij/dev_personal/nano_degree/Udacity-Projects/projects/01_fyyur/starter_code/env/lib/python3.7/site-packages/flask/app.py", line 1952, in full_dispatch_request
    rv = self.handle_user_exception(e)
  File "/home/alij/dev_personal/nano_degree/Udacity-Projects/projects/01_fyyur/starter_code/env/lib/python3.7/site-packages/flask/app.py", line 1821, in handle_user_exception
    reraise(exc_type, exc_value, tb)
  File "/home/alij/dev_personal/nano_degree/Udacity-Projects/projects/01_fyyur/starter_code/env/lib/python3.7/site-packages/flask/_compat.py", line 39, in reraise
    raise value
  File "/home/alij/dev_personal/nano_degree/Udacity-Projects/projects/01_fyyur/starter_code/env/lib/python3.7/site-packages/flask/app.py", line 1950, in full_dispatch_request
    rv = self.dispatch_request()
  File "/home/alij/dev_personal/nano_degree/Udacity-Projects/projects/01_fyyur/starter_code/env/lib/python3.7/site-packages/flask/app.py", line 1936, in dispatch_request
    return self.view_functions[rule.endpoint](**req.view_args)
  File "app.py", line 73, in venues
    venues = Venue.query.all()
  File "/home/alij/dev_personal/nano_degree/Udacity-Projects/projects/01_fyyur/starter_code/env/lib/python3.7/site-packages/flask_sqlalchemy/__init__.py", line 514, in __get__
    return type.query_class(mapper, session=self.sa.session())
  File "/home/alij/dev_personal/nano_degree/Udacity-Projects/projects/01_fyyur/starter_code/env/lib/python3.7/site-packages/sqlalchemy/orm/scoping.py", line 78, in __call__
    return self.registry()
  File "/home/alij/dev_personal/nano_degree/Udacity-Projects/projects/01_fyyur/starter_code/env/lib/python3.7/site-packages/sqlalchemy/util/_collections.py", line 1022, in __call__
    return self.registry.setdefault(key, self.createfunc())
  File "/home/alij/dev_personal/nano_degree/Udacity-Projects/projects/01_fyyur/starter_code/env/lib/python3.7/site-packages/sqlalchemy/orm/session.py", line 3286, in __call__
    return self.class_(**local_kw)
  File "/home/alij/dev_personal/nano_degree/Udacity-Projects/projects/01_fyyur/starter_code/env/lib/python3.7/site-packages/flask_sqlalchemy/__init__.py", line 137, in __init__
    track_modifications = app.config['SQLALCHEMY_TRACK_MODIFICATIONS']
KeyError: 'SQLALCHEMY_TRACK_MODIFICATIONS'
2020-10-12 11:13:19,496 INFO: errors [in app.py:961]
2020-10-12 11:13:22,220 ERROR: Exception on /venues [GET] [in /home/alij/dev_personal/nano_degree/Udacity-Projects/projects/01_fyyur/starter_code/env/lib/python3.7/site-packages/flask/app.py:1892]
Traceback (most recent call last):
  File "/home/alij/dev_personal/nano_degree/Udacity-Projects/projects/01_fyyur/starter_code/env/lib/python3.7/site-packages/sqlalchemy/util/_collections.py", line 1020, in __call__
    return self.registry[key]
KeyError: 140417255429888

During handling of the above exception, another exception occurred:

Traceback (most recent call last):
  File "/home/alij/dev_personal/nano_degree/Udacity-Projects/projects/01_fyyur/starter_code/env/lib/python3.7/site-packages/flask/app.py", line 2447, in wsgi_app
    response = self.full_dispatch_request()
  File "/home/alij/dev_personal/nano_degree/Udacity-Projects/projects/01_fyyur/starter_code/env/lib/python3.7/site-packages/flask/app.py", line 1952, in full_dispatch_request
    rv = self.handle_user_exception(e)
  File "/home/alij/dev_personal/nano_degree/Udacity-Projects/projects/01_fyyur/starter_code/env/lib/python3.7/site-packages/flask/app.py", line 1821, in handle_user_exception
    reraise(exc_type, exc_value, tb)
  File "/home/alij/dev_personal/nano_degree/Udacity-Projects/projects/01_fyyur/starter_code/env/lib/python3.7/site-packages/flask/_compat.py", line 39, in reraise
    raise value
  File "/home/alij/dev_personal/nano_degree/Udacity-Projects/projects/01_fyyur/starter_code/env/lib/python3.7/site-packages/flask/app.py", line 1950, in full_dispatch_request
    rv = self.dispatch_request()
  File "/home/alij/dev_personal/nano_degree/Udacity-Projects/projects/01_fyyur/starter_code/env/lib/python3.7/site-packages/flask/app.py", line 1936, in dispatch_request
    return self.view_functions[rule.endpoint](**req.view_args)
  File "app.py", line 74, in venues
    venues = Venue.query.all()
  File "/home/alij/dev_personal/nano_degree/Udacity-Projects/projects/01_fyyur/starter_code/env/lib/python3.7/site-packages/flask_sqlalchemy/__init__.py", line 514, in __get__
    return type.query_class(mapper, session=self.sa.session())
  File "/home/alij/dev_personal/nano_degree/Udacity-Projects/projects/01_fyyur/starter_code/env/lib/python3.7/site-packages/sqlalchemy/orm/scoping.py", line 78, in __call__
    return self.registry()
  File "/home/alij/dev_personal/nano_degree/Udacity-Projects/projects/01_fyyur/starter_code/env/lib/python3.7/site-packages/sqlalchemy/util/_collections.py", line 1022, in __call__
    return self.registry.setdefault(key, self.createfunc())
  File "/home/alij/dev_personal/nano_degree/Udacity-Projects/projects/01_fyyur/starter_code/env/lib/python3.7/site-packages/sqlalchemy/orm/session.py", line 3286, in __call__
    return self.class_(**local_kw)
  File "/home/alij/dev_personal/nano_degree/Udacity-Projects/projects/01_fyyur/starter_code/env/lib/python3.7/site-packages/flask_sqlalchemy/__init__.py", line 137, in __init__
    track_modifications = app.config['SQLALCHEMY_TRACK_MODIFICATIONS']
KeyError: 'SQLALCHEMY_TRACK_MODIFICATIONS'
2020-10-12 11:13:23,952 ERROR: Exception on /artists [GET] [in /home/alij/dev_personal/nano_degree/Udacity-Projects/projects/01_fyyur/starter_code/env/lib/python3.7/site-packages/flask/app.py:1892]
Traceback (most recent call last):
  File "/home/alij/dev_personal/nano_degree/Udacity-Projects/projects/01_fyyur/starter_code/env/lib/python3.7/site-packages/sqlalchemy/util/_collections.py", line 1020, in __call__
    return self.registry[key]
KeyError: 140417177745152

During handling of the above exception, another exception occurred:

Traceback (most recent call last):
  File "/home/alij/dev_personal/nano_degree/Udacity-Projects/projects/01_fyyur/starter_code/env/lib/python3.7/site-packages/flask/app.py", line 2447, in wsgi_app
    response = self.full_dispatch_request()
  File "/home/alij/dev_personal/nano_degree/Udacity-Projects/projects/01_fyyur/starter_code/env/lib/python3.7/site-packages/flask/app.py", line 1952, in full_dispatch_request
    rv = self.handle_user_exception(e)
  File "/home/alij/dev_personal/nano_degree/Udacity-Projects/projects/01_fyyur/starter_code/env/lib/python3.7/site-packages/flask/app.py", line 1821, in handle_user_exception
    reraise(exc_type, exc_value, tb)
  File "/home/alij/dev_personal/nano_degree/Udacity-Projects/projects/01_fyyur/starter_code/env/lib/python3.7/site-packages/flask/_compat.py", line 39, in reraise
    raise value
  File "/home/alij/dev_personal/nano_degree/Udacity-Projects/projects/01_fyyur/starter_code/env/lib/python3.7/site-packages/flask/app.py", line 1950, in full_dispatch_request
    rv = self.dispatch_request()
  File "/home/alij/dev_personal/nano_degree/Udacity-Projects/projects/01_fyyur/starter_code/env/lib/python3.7/site-packages/flask/app.py", line 1936, in dispatch_request
    return self.view_functions[rule.endpoint](**req.view_args)
  File "app.py", line 406, in artists
    all_artists = Artist.query.all()
  File "/home/alij/dev_personal/nano_degree/Udacity-Projects/projects/01_fyyur/starter_code/env/lib/python3.7/site-packages/flask_sqlalchemy/__init__.py", line 514, in __get__
    return type.query_class(mapper, session=self.sa.session())
  File "/home/alij/dev_personal/nano_degree/Udacity-Projects/projects/01_fyyur/starter_code/env/lib/python3.7/site-packages/sqlalchemy/orm/scoping.py", line 78, in __call__
    return self.registry()
  File "/home/alij/dev_personal/nano_degree/Udacity-Projects/projects/01_fyyur/starter_code/env/lib/python3.7/site-packages/sqlalchemy/util/_collections.py", line 1022, in __call__
    return self.registry.setdefault(key, self.createfunc())
  File "/home/alij/dev_personal/nano_degree/Udacity-Projects/projects/01_fyyur/starter_code/env/lib/python3.7/site-packages/sqlalchemy/orm/session.py", line 3286, in __call__
    return self.class_(**local_kw)
  File "/home/alij/dev_personal/nano_degree/Udacity-Projects/projects/01_fyyur/starter_code/env/lib/python3.7/site-packages/flask_sqlalchemy/__init__.py", line 137, in __init__
    track_modifications = app.config['SQLALCHEMY_TRACK_MODIFICATIONS']
KeyError: 'SQLALCHEMY_TRACK_MODIFICATIONS'
